Workbook

Sheet Combined
A1: Respondent ID | B1: Group | C1: Source row | D1: Interviewer | E1: Response timestamp | F1: Age | G1: Age category | H1: Gender | I1: From – State/Province | J1: From – Country | K1: From (State, Country) | L1: Residence – State/Province | M1: Residence – Country | N1: Residence (State, Country) | O1: Q5 How would you define aging? | P1: Q6 Est. % of US population 65+ | Q1: Q6 Estimate (range) | R1: Q7 Greatest challenge facing the aging population | S1: Q8 Challenge to solve in the short term | T1: Q8 Why prioritize it | U1: Q9 Action being taken on this challenge? | V1: Q10 Three things to maintain through life | W1: Q11 What you can do to maintain them | X1: Q12 Description of the three topics | Y1: Personal rank – Reproductive health & longevity | Z1: Personal rank – Democratizing longevity | AA1: Personal rank – AI/ML for aging & health | AB1: Societal rank – Reproductive health & longevity | AC1: Societal rank – Democratizing longevity | AD1: Societal rank – AI/ML for aging & health | AE1: Reason for ranking | AF1: Most exciting topic | AG1: What excites you | AH1: Most concerning topic | AI1: Greatest concern | AJ1: Ethical considerations needed? | AK1: Ethical considerations (details) | AL1: Excited about future of aging research? | AM1: Excitement rating (1–5) | AN1: Excitement comment | AO1: Bioengineers can help? | AP1: Bioengineer role rating (1–5) | AQ1: Bioengineers comment | AR1: Data notes
A2: G1-001 | B2: 1 | C2: 2 | F2: 25 | G2: =IF(F2="","",IF(F2>=Notes!$B$5,"Elderly ("&Notes!$B$5&"+)",IF(F2<=Notes!$B$4,"Student age (≤"&Notes!$B$4&")","Middle-aged ("&(Notes!$B$4+1)&"–"&(Notes!$B$5-1)&")"))) -> Student age (≤29) | H2: Female | I2: Florida | J2: United States | K2: Florida, United States | L2: Maryland | M2: United States | N2: Maryland, United States | O2: Biological and physical changes as a result of time passing! | P2: 35 | Q2: Over 30% | R2: Not enough access to medical care/practitioners. | S2: Promote programs to get more caregivers/nursing home attendants | U2: Programs to sponsor people who plan to be or are caregivers (forgiven college debts), subsidies, free food delivery programs for elderly | V2: My mind, my friends, my ability to move easily | W2: Yoga, reading, going to yoga with friends lol | Y2: 3 | Z2: 1 | AA2: 2 | AB2: 2 | AC2: 1 | AD2: 3 | AG2: As a woman, it is scary to feel pressured to have children when there is little access to good childcare for working women. | AJ2: Yes | AL2: Yes | AO2: Yes
A3: G1-002 | B3: 1 | C3: 3 | F3: 24 | G3: =IF(F3="","",IF(F3>=Notes!$B$5,"Elderly ("&Notes!$B$5&"+)",IF(F3<=Notes!$B$4,"Student age (≤"&Notes!$B$4&")","Middle-aged ("&(Notes!$B$4+1)&"–"&(Notes!$B$5-1)&")"))) -> Student age (≤29) | H3: Female | I3: Pennsylvania | J3: United States | K3: Pennsylvania, United States | L3: Maryland | M3: United States | N3: Maryland, United States | O3: body tissues breaking down, mind gaining experience | P3: 38 | Q3: Over 30% | R3: social support | S3: healthcare resource availability | U3: ehh not really | V3: mental clarity, mental health, mobility | W3: eat good sleep good exercise good protect my relationships | Y3: 2 | Z3: 1 | AA3: 3 | AB3: 3 | AC3: 2 | AD3: 1 | AG3: dementia | AJ3: Yes | AL3: Yes | AO3: Yes
A4: G1-003 | B4: 1 | C4: 4 | F4: 19 | G4: =IF(F4="","",IF(F4>=Notes!$B$5,"Elderly ("&Notes!$B$5&"+)",IF(F4<=Notes!$B$4,"Student age (≤"&Notes!$B$4&")","Middle-aged ("&(Notes!$B$4+1)&"–"&(Notes!$B$5-1)&")"))) -> Student age (≤29) | H4: Female | I4: California | J4: United States | K4: California, United States | L4: Maryland | M4: United States | N4: Maryland, United States | O4: Scary | P4: 10 | Q4: 15% or less | R4: Lack of preventative medicine so diseases and illnesses get caught too late. | S4: Preventative medicine can help prevent consequences that later on can be more costly and painful, if we can figure out a way to encourage more people and to get people more access to said preventative medicine in the short term it will solve a lot of our long term problems. | U4: No, our administration cuts budgets and doesn’t make healthcare more accessible. | V4: Family, physical & mental health | W4: I can keep showing up for people to maintain my community, I can also keep going to check ups and I can pay attention to nutrition and exercise in order to keep my health up. | Y4: 3 | Z4: 3 | AA4: 2 | AB4: 2 | AC4: 1 | AD4: 1 | AG4: I mean the concept of AI taking over our healthcare system is scary but it’s also exciting because it may be a lot more accessible to more people. | AJ4: Yes | AL4: Yes | AO4: Yes | AR4: personal ranks repeat a number (as answered); societal ranks repeat a number (as answered)
A5: G1-004 | B5: 1 | C5: 5 | F5: 21 | G5: =IF(F5="","",IF(F5>=Notes!$B$5,"Elderly ("&Notes!$B$5&"+)",IF(F5<=Notes!$B$4,"Student age (≤"&Notes!$B$4&")","Middle-aged ("&(Notes!$B$4+1)&"–"&(Notes!$B$5-1)&")"))) -> Student age (≤29) | H5: Male | I5: Maryland | J5: United States | K5: Maryland, United States | L5: Maryland | M5: United States | N5: Maryland, United States | O5: telomere degradation | P5: 40 | Q5: Over 30% | R5: Rising technological advances resulting in increased ignorance | S5: Lack of help - basic needs -> foundations of a healthy life | U5: Reformation of nursing homes and communities currently, but unfortunately insufficient | V5: youthful personality, athleticism, and drive | W5: education | Y5: 3 | Z5: 2 | AA5: 1 | AB5: 3 | AC5: 2 | AD5: 1 | AG5: AI predicting modern solutions - both excites me for the future of medicine, but also frightens me for the upcoming consequences | AJ5: Yes | AL5: Yes | AO5: Yes
A6: G1-005 | B6: 1 | C6: 6 | F6: 21 | G6: =IF(F6="","",IF(F6>=Notes!$B$5,"Elderly ("&Notes!$B$5&"+)",IF(F6<=Notes!$B$4,"Student age (≤"&Notes!$B$4&")","Middle-aged ("&(Notes!$B$4+1)&"–"&(Notes!$B$5-1)&")"))) -> Student age (≤29) | H6: Male | I6: Massachusetts | J6: United States | K6: Massachusetts, United States | L6: Maryland | M6: United States | N6: Maryland, United States | O6: Cellular aging | P6: 20 | Q6: 16–20% | R6: Aging with dignity | S6: Demograohic cliff cannot financially support elder cohort | U6: No | V6: Money, movement, mental acuity | W6: Healthy lifestyle | X6: Small tradeoffs now that support longefvkty | Y6: 2 | Z6: 1 | AA6: 3 | AB6: 2 | AC6: 1 | AD6: 3 | AE6: Idk | AG6: Idk | AJ6: Yes | AL6: No | AO6: No
A7: G1-006 | B7: 1 | C7: 7 | F7: 24 | G7: =IF(F7="","",IF(F7>=Notes!$B$5,"Elderly ("&Notes!$B$5&"+)",IF(F7<=Notes!$B$4,"Student age (≤"&Notes!$B$4&")","Middle-aged ("&(Notes!$B$4+1)&"–"&(Notes!$B$5-1)&")"))) -> Student age (≤29) | H7: Male | I7: California | J7: United States | K7: California, United States | L7: California | M7: United States | N7: California, United States | O7: Getting older | P7: 32 | Q7: Over 30% | R7: Dealing with all sorts of age-related diseases/complications | S7: Preventative health so we are proactive instead of reactive | U7: R&D | V7: Vision; Lucidity; Athleticism | W7: Workout; Dont use too many screens; Puzzles | X7: Enjoying life | Y7: 2 | Z7: 1 | AA7: 3 | AB7: 2 | AC7: 1 | AD7: 3 | AE7: I want to be healthy | AG7: Longer healthier lives; AI taking over the world | AJ7: Yes | AL7: Yes | AO7: Yes
A8: G1-007 | B8: 1 | C8: 10 | F8: 20 | G8: =IF(F8="","",IF(F8>=Notes!$B$5,"Elderly ("&Notes!$B$5&"+)",IF(F8<=Notes!$B$4,"Student age (≤"&Notes!$B$4&")","Middle-aged ("&(Notes!$B$4+1)&"–"&(Notes!$B$5-1)&")"))) -> Student age (≤29) | H8: Male | I8: Michigan | J8: United States | K8: Michigan, United States | L8: Maryland | M8: United States | N8: Maryland, United States | O8: Chronologically getting older, or biologically degrading telomeres | P8: 25 | Q8: 21–30% | R8: More and more aging population, but less and less resources to care for them (both monetarily but also human-labor wise) | S8: Find people that are able to give that care at an affordable pace, because without the promise of a worthwhile retirement (age) then people grow less motivated and more focused on trying to make their prime the best it can be. | U8: Make day to day life easier by offering ways for families to take care of their elderly members (leave from work, stipend, etc.) | V8: Physical mobility, cognition (mentally active, lose consciouness and become a shell), keep up with the times (not getting stuck in a mindset) | W8: Keep an open mind, stay healthy be exercising, don’t get complacent about doing things. | X8: Applying modern tech solutions to current problems | Y8: 2 | Z8: 1 | AA8: 3 | AB8: 2 | AC8: 1 | AD8: 3 | AE8: If you can apply broader health impacts across all walks of life, they would most impact people at the current timeframe, but also probably as they grow older they maintain healthier habits and benefits so it’s more lifelong than specific moments. | AG8: Not really exciting, but more of a necessity of things that have to happen if we want our lives to get better. There isn’t enough of a rush or consideration for it in the grand scheme of things currently going on, so much division that there isn’t time to focus on these issues | AJ8: Yes | AL8: Yes | AO8: Yes
A9: G1-008 | B9: 1 | C9: 11 | F9: 20 | G9: =IF(F9="","",IF(F9>=Notes!$B$5,"Elderly ("&Notes!$B$5&"+)",IF(F9<=Notes!$B$4,"Student age (≤"&Notes!$B$4&")","Middle-aged ("&(Notes!$B$4+1)&"–"&(Notes!$B$5-1)&")"))) -> Student age (≤29) | H9: Male | I9: Georgia | J9: United States | K9: Georgia, United States | L9: Maryland | M9: United States | N9: Maryland, United States | O9: Growing older | P9: 12 | Q9: 15% or less | R9: Loneliness | S9: General healthiness | U9: Yes, more mental wellbeing being understood and addressed, people starting to be more active on social media | V9: Health, mental acuity, friends | W9: Maintain good habits, read books, good communication | X9: Three different angles to improving health | Y9: 2 | Z9: 3 | AA9: 1 | AB9: 3 | AC9: 1 | AD9: 2 | AE9: Accessibility to these longevity/health solutions isn’t as important to me as it is for society since I already have access and have a lesser need for them since I am young. I would be more interested in accelerating research in longevity/health. To society, however, accessibility is the most important as everyone deserves a baseline level of access to currently existing science/solutions. | AG9: Iii, it’s newer, and things that leverage ai just excite me personally. We also have a ton of data compiled from years of research. Something that comes to mind is the PDB. The concern though is that it’s newer so there are potential unknown risks of unknown magnitude. | AJ9: Yes | AL9: Yes | AO9: Yes
A10: G1-009 | B10: 1 | C10: 12 | F10: 21 | G10: =IF(F10="","",IF(F10>=Notes!$B$5,"Elderly ("&Notes!$B$5&"+)",IF(F10<=Notes!$B$4,"Student age (≤"&Notes!$B$4&")","Middle-aged ("&(Notes!$B$4+1)&"–"&(Notes!$B$5-1)&")"))) -> Student age (≤29) | H10: Male | I10: Maryland | J10: United States | K10: Maryland, United States | L10: Maryland | M10: United States | N10: Maryland, United States | O10: The process of integrating learned/life experiences throughout one's lifetime. | P10: 30 | Q10: 21–30% | R10: Access to healthcare and socialization | S10: Socialization as issues with healthcare are particularly geared toward a specific group of people while most if not all elderly find it difficult to socialize. | U10: Yes through different social groups or spaces, such as church or even small groups/ clubs. | V10: My memory, cognitive ability, and physical ability. | W10: Maintain my mental and physical routine throughout my lifetime, even as i get older. | X10: (i) Taking action to increase one’s ability to participate in reproductive activities in a healthy way; (ii) Increasing access to healthcare to improve quality of life; (iii) Using AI to inform oneself and others about potential solutions to aging | Y10: 2 | Z10: 1 | AA10: 3 | AB10: 2 | AC10: 3 | AD10: 1 | AE10: I prioritize making health more accessible to others, while I feel as if general society wants to capitalize on the advancements in AI to find an optimal approach to aging. | AG10: ii is most exciting while iii is most concerning. | AJ10: Yes | AL10: Yes | AO10: Yes
A11: G1-010 | B11: 1 | C11: 15 | F11: 20 | G11: =IF(F11="","",IF(F11>=Notes!$B$5,"Elderly ("&Notes!$B$5&"+)",IF(F11<=Notes!$B$4,"Student age (≤"&Notes!$B$4&")","Middle-aged ("&(Notes!$B$4+1)&"–"&(Notes!$B$5-1)&")"))) -> Student age (≤29) | H11: Male | I11: Maryland | J11: United States | K11: Maryland, United States | L11: Maryland | M11: United States | N11: Maryland, United States | O11: Being alive for longer | P11: 32 | Q11: Over 30% | R11: Medical care/retirement funds | S11: Not enough tax money to pay the retirement funds of the aging population. | U11: Increase retirement age or remove social security. | V11: Money; Health; Family | W11: Make sure I make enough money to keep my health and family. | X11: Complex solutions to health | Y11: 1 | Z11: 3 | AA11: 2 | AB11: 1 | AC11: 3 | AD11: 2 | AE11: Health is most important for life. Money is required for health. | AG11: Excited for boosting reproductive health and longevity lets me live longer and feel better as I live longer. I’m afraid that capitalism will commercialize health even more and make it inaccessible to lower middle income individuals. | AJ11: Yes | AL11: Yes | AO11: Yes
A12: G1-011 | B12: 1 | C12: 18 | F12: 22 | G12: =IF(F12="","",IF(F12>=Notes!$B$5,"Elderly ("&Notes!$B$5&"+)",IF(F12<=Notes!$B$4,"Student age (≤"&Notes!$B$4&")","Middle-aged ("&(Notes!$B$4+1)&"–"&(Notes!$B$5-1)&")"))) -> Student age (≤29) | H12: Female | I12: New York | J12: United States | K12: New York, United States | L12: Maryland | M12: United States | N12: Maryland, United States | O12: I think aging is defined as the physical and metabolic/molecular changes that occur within an individual. I believe that there are genetic and environmental factors that can help or hinder a person’s aging rate. I also think that aging is unique to each person because of these factors. | P12: 30 | Q12: 21–30% | R12: maybe disengagement theory- being ostracized from the population which can lead to feeling alienated from dominant society. | S12: I think that the greatest challenge facing our aging population could possibly be them feeling ostracized from the general public, which can affect their mental health and thus cause other health problems. | U12: Not really. I feel like it’s normal for people to do things with their own age group so that might be a reason why I personally don’t see aging populations doing activities that I like to do. | V12: Doing wellness activities (ex. running), reading a lot, being happy. | W12: join groups that are involved in running and living a healthy lifestyle. And hanging out with people who had the same mindset and ideals as me. | X12: do you mean a lot because they define my morals and what my parents and other have taught me to live a fulfilling life. | Y12: 1 | Z12: 2 | AA12: 3 | AB12: 2 | AC12: 1 | AD12: 3 | AE12: I think people will look at things, face value and care about if the solutions are affordable and accessible to them. | AG12: I hope that one day, solutions to aging become accessible to the general public and aren’t expensive and only available to the rich. | AJ12: Yes | AL12: Yes | AO12: Yes
A13: G1-012 | B13: 1 | C13: 19 | F13: 22 | G13: =IF(F13="","",IF(F13>=Notes!$B$5,"Elderly ("&Notes!$B$5&"+)",IF(F13<=Notes!$B$4,"Student age (≤"&Notes!$B$4&")","Middle-aged ("&(Notes!$B$4+1)&"–"&(Notes!$B$5-1)&")"))) -> Student age (≤29) | H13: Male | I13: Texas | J13: United States | K13: Texas, United States | L13: Maryland | M13: United States | N13: Maryland, United States | O13: The passage of time | P13: 25 | Q13: 21–30% | R13: Social security is inadequate for our increasingly aged country | S13: Aged population growth is accelerating while birth rate is declining, having the young take care of the old financially through social security is infeasible, and changes need to be addressed now before the population collapses similar to Korea. | U13: Increase the retirement age. | V13: My physical, mental, and financial health. | W13: Workout and invest heavily | X13: Invest in my future in all aspects of my life. | Y13: 1 | Z13: 2 | AA13: 3 | AB13: 2 | AC13: 1 | AD13: 3 | AE13: I think AI will significantly accelerate aging research which will be helpful for everyone. | AG13: Rich people will live longer and control more. | AJ13: Yes | AL13: No | AO13: Yes
A14: G1-013 | B14: 1 | C14: 20 | F14: 22 | G14: =IF(F14="","",IF(F14>=Notes!$B$5,"Elderly ("&Notes!$B$5&"+)",IF(F14<=Notes!$B$4,"Student age (≤"&Notes!$B$4&")","Middle-aged ("&(Notes!$B$4+1)&"–"&(Notes!$B$5-1)&")"))) -> Student age (≤29) | H14: Male | I14: Maryland | J14: United States | K14: Maryland, United States | L14: California | M14: United States | N14: California, United States | O14: Being alive longer? | P14: 30 | Q14: 21–30% | R14: Healthcare Costs | S14: Healthcare, everyone gets old and more prone to hospital visits. | U14: Honestly no. I know this is unpopular in the largely democratic hopkins space and I am up in the air about how much I truly believe in this idea, I am also kinda ignorant in this topic specifically because I don’t really think or care about the older population very much at this point in my life.; But privatizing advanced medicine isn’t the worst thing in the world. People over 65 already spend a ton of money on healthcare, especially in the last 12 months of life. In the event we spend more money on the elderly what is the end goal? We have a bunch of people who aren’t working and live even longer for what purpose? Especially those who are sick and are living heavily impacted lives. I agree that people who have been working a long time should be rewarded with years of retirement, and that it is truly a matter of luck whether you get to experience those years, but I think it isnt the worst idea in the world for people who have amassed wealth in their life to have better resources for living longer than someone who hasn’t.; To tie a personal story into this. My mom was diagnosed with stage 4 breast cancer about 2 years ago. Shes been doing chemo to minimize and hold out for a vaccine to cure her cancer. Now I don’t actually know how much she is spending on this treatment, but she has amassed 7 figures at least in her 401k (which she can’t even access because shes not 58 or whatever age it is), and she still has money from selling her nice house and moving to Mississippi with my white ass family where cost of living is cheap. All of that is to say, she has had the luxury of fighting this cancer, despite her hating every second, because she made a solid money in her time. Its not like she had generational wealth, she grew up on a farm, and she was the first person in her family to go to graduate school. She just worked really hard to make money and provide for us, another reason why she was able to send me to JHU.; Now obviously nobody is saying that people who have a lot of money shouldnt be allowed to spend their money on their illnesses as an elderly adult. But we both know as people in medicine how expensive it is to get these clinical trials completed and develop the medicine.; I have been working heavily in medicine recently and have learned alot about the grueling process of doing research, developing a drug, and going through the steps of approval for that drug. Its expensive and labor intensive. That costs money, like a lot. So that money is either coming out of our pockets in taxes, or the elderly pockets. I do believe that we should continue spending as a society for the elderly to have care, but there is certainly risk in heavily democratizing care. Do we as a society really benefit from having a bunch of sick old people spending a bunch of money prolonging their life? Honestly, I dont think so. Everybody experiences the loss of their parents, I personally haven’t yet, but I know I will and that reality has been staring me in the face a while. I feel that spending all this money on elderly care just is not the best way forward and I dont see the benefit of spending much more on it. Now I certainly believe the system that needs the most revision is insurance, they make an exuberant amount of money, and this system should exist for people who are unlucky in their younger years and are threatened with the reality that they won’t make it to those retirement years. For people like my mom who have worked hard providing for me and my brother as a single mom and can’t access the 401k money she has saved, I would say insurance and spending exist for them. I understand I am biased and that this logic doesn’t exist for people who aren’t able to save enough money to really retire but that second point is a different story.; I am tired of typing this out I have other things to do, but I did want to provide my perspective, honestly not for you, but for me to be able to get my thoughts on a page and further develop a thought that was sneaking around in the back of my brain and I wanted to understand it.; Alright good luck with this study, and we should probably wish Landon luck because he is about to soend the day at wafflehouse. I will say though good for club basketball because unless he packed on hella weight since I last saw him, he needs it. | V14: Friends, my partner, money | W14: Put extra effort into relationships, make a ton of money | X14: sorry nah | Y14: 1 | Z14: 2 | AA14: 3 | AB14: 1 | AC14: 3 | AD14: 2 | AE14: Healthcare is the most important, AI this AI that whatever, just take viagra tbh; For me I build CNNs and so I care more about AI applications but the other logic is consistent. | AG14: I dont see healthcare changing so its worrying that I will get old and have these issues. I am excited to party with the boys in the retirement home 🎉 | AJ14: Yes | AL14: Yes | AO14: Yes
A15: G1-014 | B15: 1 | C15: 33 | F15: 24 | G15: =IF(F15="","",IF(F15>=Notes!$B$5,"Elderly ("&Notes!$B$5&"+)",IF(F15<=Notes!$B$4,"Student age (≤"&Notes!$B$4&")","Middle-aged ("&(Notes!$B$4+1)&"–"&(Notes!$B$5-1)&")"))) -> Student age (≤29) | H15: Female | I15: Florida | J15: United States | K15: Florida, United States | L15: Maryland | M15: United States | N15: Maryland, United States | O15: The age increasing in number (but != lack of health) | P15: 23 | Q15: 21–30% | R15: Loneliness | S15: Access to healthcare, because everyone deserves equitable healthcare | U15: Medicare has specific initiatives for dementia and other conditions which is good | V15: Health, Energy, Community | W15: Exercise regularly and eat healthy | X15: Capital H Health (not episodic lowercase h health) | Y15: 3 | Z15: 1 | AA15: 2 | AB15: 2 | AC15: 3 | AD15: 1 | AE15: There’s more money going into AI applications and longer reproductive health (IVF, etc) than general healthy aging | AG15: AI/ML pervasively used in everything | AJ15: Yes | AL15: Yes | AO15: Yes
A16: G1-015 | B16: 1 | C16: 34 | F16: 23 | G16: =IF(F16="","",IF(F16>=Notes!$B$5,"Elderly ("&Notes!$B$5&"+)",IF(F16<=Notes!$B$4,"Student age (≤"&Notes!$B$4&")","Middle-aged ("&(Notes!$B$4+1)&"–"&(Notes!$B$5-1)&")"))) -> Student age (≤29) | H16: Male | I16: Florida | J16: United States | K16: Florida, United States | L16: Maryland | M16: United States | N16: Maryland, United States | O16: Levels of Aura | P16: 20 | Q16: 16–20% | R16: Health Care | S16: Lack of health care | U16: More Awareness | V16: 1. Gym Gains; 2. Healthy body; 3. Mobility | W16: Go to Gym | X16: Going to gym and follow routine | Y16: 1 | Z16: 2 | AA16: 3 | AB16: 2 | AC16: 3 | AD16: 1 | AE16: I care about myself rather than training ML models | AG16: The thing that excites me is my determination to get jacked and what scares me is aging | AJ16: No | AL16: Yes | AO16: Yes
A17: G1-016 | B17: 1 | C17: 37 | F17: 22 | G17: =IF(F17="","",IF(F17>=Notes!$B$5,"Elderly ("&Notes!$B$5&"+)",IF(F17<=Notes!$B$4,"Student age (≤"&Notes!$B$4&")","Middle-aged ("&(Notes!$B$4+1)&"–"&(Notes!$B$5-1)&")"))) -> Student age (≤29) | H17: Male | J17: United States | K17: United States | M17: United States | N17: United States | O17: The growth and eventually biological deterioration of the human body and the mind over the course of time | P17: 30 | Q17: 21–30% | R17: Alzheimer’s and chronic illnesses | S17: Healthcare claims | U17: Easier access to healthcare | V17: memory family and health | W17: working out, focus on relationships and mindfulness | X17: Personal growth | Y17: 1 | Z17: 2 | AA17: 3 | AB17: 3 | AC17: 1 | AD17: 2 | AE17: Society vs personal different | AG17: Ai can work i have faith in precision medicine. Frightens is prolly ai too strong and sentient | AJ17: Yes | AL17: Yes | AO17: Yes
A18: G1-017 | B18: 1 | C18: 38 | F18: 24 | G18: =IF(F18="","",IF(F18>=Notes!$B$5,"Elderly ("&Notes!$B$5&"+)",IF(F18<=Notes!$B$4,"Student age (≤"&Notes!$B$4&")","Middle-aged ("&(Notes!$B$4+1)&"–"&(Notes!$B$5-1)&")"))) -> Student age (≤29) | H18: Male | I18: Florida | J18: United States | K18: Florida, United States | L18: Maryland | M18: United States | N18: Maryland, United States | O18: Revolutions around the sun; growth and subsequent decline of physical and mental capacity | P18: 40 | Q18: Over 30% | R18: Disease | S18: Not enough medical workforce to care for aging population | U18: incentives for workforce/nursing | V18: memory, walking, hand mobility | W18: exercise, eat healthy | X18: Take care of your own health | Y18: 3 | Z18: 2 | AA18: 1 | AB18: 3 | AC18: 1 | AD18: 2 | AE18: access is important. we have high population, reproduction might hurt. | AG18: excite: personal medicine. frighten: increased lifespan without health | AJ18: Yes | AL18: Yes | AO18: Yes
A19: G1-018 | B19: 1 | C19: 39 | F19: 22 | G19: =IF(F19="","",IF(F19>=Notes!$B$5,"Elderly ("&Notes!$B$5&"+)",IF(F19<=Notes!$B$4,"Student age (≤"&Notes!$B$4&")","Middle-aged ("&(Notes!$B$4+1)&"–"&(Notes!$B$5-1)&")"))) -> Student age (≤29) | H19: Male | I19: Massachusetts | J19: United States | K19: Massachusetts, United States | L19: Maryland / New Jersey | M19: United States | N19: Maryland / New Jersey, United States | O19: Simply an organism’s forward progression through time. | P19: 15 | Q19: 15% or less | R19: A lot of things; Economically: food insecurity and housing; Biologically: disease, widespread pandemics etc; Epistemologically: AI pollution on the internet and the increasing unverifiability of information; Societally: loneliness; Ecologically: climate change; And much more | S19: No problem worth solving at this scale is solved quickly | U19: Nope. | V19: My mental function; As much athleticism as possible; My penis | W19: Lock in | X19: Read bruh. It’s pretty clear | Y19: 2 | Z19: 1 | AA19: 3 | AB19: 2 | AC19: 3 | AD19: 1 | AE19: Because I think affordable healthcare and actual outcomes matter first more than new discoveries in medicine. More direct impact would easily come from actually applying what we do have currently than from throwing compute at stuff to discover more. That’s important too, but unfortunately society, specifically the tech giants, only care about the frontier and none of the ground level reality of it. | AG19: Nothing scares me.; Everything excited me.; What can I say I’m a chill guy/gal | AJ19: Yes | AL19: Yes | AO19: Yes
A20: G1-019 | B20: 1 | C20: 47 | F20: 26 | G20: =IF(F20="","",IF(F20>=Notes!$B$5,"Elderly ("&Notes!$B$5&"+)",IF(F20<=Notes!$B$4,"Student age (≤"&Notes!$B$4&")","Middle-aged ("&(Notes!$B$4+1)&"–"&(Notes!$B$5-1)&")"))) -> Student age (≤29) | H20: Male | I20: New York | J20: United States | K20: New York, United States | L20: New York | M20: United States | N20: New York, United States | O20: Changes that arise from the passage of time | P20: 15 | Q20: 15% or less | R20: Understanding modern technology and the decline of in-person socialization | S20: In-person socialization and engagement, use of technology. For the former, benefits to health and reducing isolation is very good individually and for society; for the latter, it is important to accommodate and provide services for people that do not freeze out those who are not as familiar, adept, or comfortable with certain technological changes in day-to-day life | U20: Yes. Prioritizing third spaces again, requiring certain provisions in services (physical menus, for example, not just QR codes in restaurants) | V20: -Active lifestyle; -Connection with community and friends; -Travel | W20: Yes. Build foundation and connections, maintain them, prioritize my health throughout my life | X20: Health is wealth | Y20: 2 | Z20: 2 | AA20: 1 | AB20: 3 | AC20: 3 | AD20: 1 | AE20: I am not as concerned individually as society and countries are (and rightfully in many ways) with the problems of aging. I am not in favor of the "break things fast" model of AI development, and although widely used and useful in science, am not sure how important or useful it is or should be in this particular field | AG20: The incredible advancement of science and understanding of biology excites me; the trajectory and reality of widespread AI use without proper regulations and restrictions does not. | AJ20: No | AL20: No | AO20: Yes | AR20: personal ranks repeat a number (as answered); societal ranks repeat a number (as answered)
A21: G1-020 | B21: 1 | C21: 50 | F21: 24 | G21: =IF(F21="","",IF(F21>=Notes!$B$5,"Elderly ("&Notes!$B$5&"+)",IF(F21<=Notes!$B$4,"Student age (≤"&Notes!$B$4&")","Middle-aged ("&(Notes!$B$4+1)&"–"&(Notes!$B$5-1)&")"))) -> Student age (≤29) | H21: Male | I21: Connecticut | J21: United States | K21: Connecticut, United States | L21: Ohio | M21: United States | N21: Ohio, United States | O21: Moving through the years of your life and the experiences that comes with that | P21: 30 | Q21: 21–30% | R21: The ability to understand technology and not be threatened by it or afraid of it | S21: I think offering simpler ways to go about daily tasks that ease in the use of technology would help out | U21: It would be difficult to give everyone access to technology in a short time frame | V21: 1. Ability to connect with people from other generations; 2. Ability to use technology on my own; 3. The desire to still interact with others in the world aside from my immediate family | W21: I can get out and go meet people and build lasting relationships that are important to me | X21: Make an effort to develop your character when you’re young so you are not an outcast when you are old | Y21: 2 | Z21: 2 | AA21: 3 | AB21: 1 | AC21: 1 | AD21: 2 | AE21: I think society does not put an extreme emphasis or importance on ensuring all people are given equal opportunity or the tools to succeed | AG21: Exciting: the development of technology to enhance our day to day life; Frighten: the ability for all to access this technology | AJ21: Yes | AL21: Yes | AO21: Yes | AR21: personal ranks repeat a number (as answered); societal ranks repeat a number (as answered)
A22: G1-021 | B22: 1 | C22: 53 | F22: 28 | G22: =IF(F22="","",IF(F22>=Notes!$B$5,"Elderly ("&Notes!$B$5&"+)",IF(F22<=Notes!$B$4,"Student age (≤"&Notes!$B$4&")","Middle-aged ("&(Notes!$B$4+1)&"–"&(Notes!$B$5-1)&")"))) -> Student age (≤29) | H22: Male | I22: New York | J22: United States | K22: New York, United States | L22: Maryland | M22: United States | N22: Maryland, United States | O22: The generally worsening health and performance outcomes associated with increasing age. | P22: 20 | Q22: 16–20% | R22: Beyond the medical needs that have beset every generation as it ages, the greatest challenge may be the financial burden of providing adequate care to the larger share of Americans who will be retired. | S22: For retired Americans, keeping social security solvent will be important in the next few decades, along with ensuring that social welfare programs cover the medical and financial needs of aging populations more broadly, even as workforce participation may decline due to that aging population. | U22: Likely an increase in the retirement age, but also a larger, more efficient welfare state. | V22: My physical and mental abilities, my health, and my social circle. | W22: Exercise and diet along with preventative care for the first two. For the third, being proactive about socialization | X22: These three things mean my ability to have a fulfilling and active life. | Y22: 1 | Z22: 2 | AA22: 3 | AB22: 2 | AC22: 1 | AD22: 3 | AE22: I believe my socio-economic status means that making longevity science more democratic won't be important to me as an individual, but will be very important to society. The third option reads to me as a means to the first two and so I ranked it lowest. | AG22: I'm excited by the future prospects of longevity science, particularly in how it will let me lead a longer and more fulfilling life. I am concerned by the societal implications of an older society that has not accounted for slower turnover, greater medical costs, etc. | AJ22: Yes | AL22: Yes | AO22: Yes
A23: G1-022 | B23: 1 | C23: 54 | F23: 21 | G23: =IF(F23="","",IF(F23>=Notes!$B$5,"Elderly ("&Notes!$B$5&"+)",IF(F23<=Notes!$B$4,"Student age (≤"&Notes!$B$4&")","Middle-aged ("&(Notes!$B$4+1)&"–"&(Notes!$B$5-1)&")"))) -> Student age (≤29) | H23: Male | I23: California | J23: United States | K23: California, United States | L23: Maryland | M23: United States | N23: Maryland, United States | O23: Body and health deteriorating as you get older | P23: 20 | Q23: 16–20% | R23: Lack of social services | S23: More care centers and promotion of assisted living homes, since many people lack support systems | U23: Opening more facilities | V23: Mobility, independence, energy | W23: Exercise and healthy lifestyle | X23: Be consistent with activity and prioritize longevity over short-term comfort | Y23: 3 | Z23: 3 | AA23: 2 | AB23: 2 | AC23: 1 | AD23: 3 | AE23: I think using modern tech to address these challenges is still a bit premature since we lack the infrastructure to even support them | AG23: Its exciting that advances are being made but frightening that they may not be developed quickly enough for our loved ones and even our own generation | AJ23: Yes | AL23: Yes | AO23: Yes | AR23: personal ranks repeat a number (as answered)
A24: G1-023 | B24: 1 | C24: 55 | F24: 21 | G24: =IF(F24="","",IF(F24>=Notes!$B$5,"Elderly ("&Notes!$B$5&"+)",IF(F24<=Notes!$B$4,"Student age (≤"&Notes!$B$4&")","Middle-aged ("&(Notes!$B$4+1)&"–"&(Notes!$B$5-1)&")"))) -> Student age (≤29) | H24: Male | I24: New Jersey | J24: United States | K24: New Jersey, United States | L24: Maryland | M24: United States | N24: Maryland, United States | O24: Decline of our bodily functions as time passes | P24: 20 | Q24: 16–20% | R24: Too prone to injury | S24: Injuries in the shower should be prioritized because it can be fixed very easily via secure shower mats. | U24: Yes, provide elderly with secure shower mats | V24: Lifting progress, young face, knowledge | W24: Exercise, good sleep, continuing to learn | X24: They mean good healthy both physically and mentally. | Y24: 1 | Z24: 2 | AA24: 3 | AB24: 1 | AC24: 3 | AD24: 2 | AE24: I am a big proponent for AI and think it has huge medical applications. However, I do think that healthcare is too expensive and needs to undergo economic change to become more affordable for Americans. | AG24: Making healthcare affordable will relieve a lot of stress on families but will probably cause another sector's price to spike. | AJ24: Yes | AL24: No | AO24: Yes
A25: G1-024 | B25: 1 | C25: 56 | F25: 18 | G25: =IF(F25="","",IF(F25>=Notes!$B$5,"Elderly ("&Notes!$B$5&"+)",IF(F25<=Notes!$B$4,"Student age (≤"&Notes!$B$4&")","Middle-aged ("&(Notes!$B$4+1)&"–"&(Notes!$B$5-1)&")"))) -> Student age (≤29) | H25: Female | I25: New Jersey | J25: United States | K25: New Jersey, United States | L25: New Jersey | M25: United States | N25: New Jersey, United States | O25: Aging is a developmental part of life that can result in both negative and positive changes in a person | P25: 25 | Q25: 21–30% | R25: Perhaps the lack of willingness to understand them and remember that they are people too, not just things to be taken care of and they once lived the same lives as every young person. | S25: The literacy crisis so that the risk of dementia decreases | U25: Yes, hopefully the government and Department of Education take charge of this matter | V25: My intelligence, my relationships, and my reputation | W25: I can make them a priority and keep making sure I talk to people to learn from them | X25: They shape who I am as a human being. | Y25: 1 | Z25: 2 | AA25: 3 | AB25: 2 | AC25: 1 | AD25: 3 | AE25: I think affordability is one of the foremost issues people have and people are always finding remedies to live longer, which is why I consistently ranked those two as my top two. | AG25: I’m afraid that the sensitive data the AI could contain might be stolen. I’m excited by the thought of AI being able to help cure diseases. | AJ25: Yes | AL25: Yes | AO25: Yes
A26: G1-025 | B26: 1 | C26: 57 | F26: 21 | G26: =IF(F26="","",IF(F26>=Notes!$B$5,"Elderly ("&Notes!$B$5&"+)",IF(F26<=Notes!$B$4,"Student age (≤"&Notes!$B$4&")","Middle-aged ("&(Notes!$B$4+1)&"–"&(Notes!$B$5-1)&")"))) -> Student age (≤29) | H26: Male | I26: California | J26: United States | K26: California, United States | L26: Maryland | M26: United States | N26: Maryland, United States | O26: getting older | P26: 25 | Q26: 21–30% | R26: unable to keep up with technological advancements and health | S26: technological literacy because it is fairly straightforward | U26: policies or pubic awareness campaigns | V26: friends, family, income or job | W26: reminders or continuous check-ups | X26: they are special to me | Y26: 3 | Z26: 1 | AA26: 2 | AB26: 2 | AC26: 1 | AD26: 3 | AE26: reproductive health is important to society | AG26: AI has vast potential | AJ26: Yes | AL26: Yes | AO26: Yes
A27: G1-026 | B27: 1 | C27: 58 | F27: 21 | G27: =IF(F27="","",IF(F27>=Notes!$B$5,"Elderly ("&Notes!$B$5&"+)",IF(F27<=Notes!$B$4,"Student age (≤"&Notes!$B$4&")","Middle-aged ("&(Notes!$B$4+1)&"–"&(Notes!$B$5-1)&")"))) -> Student age (≤29) | H27: Male | I27: Florida | J27: United States | K27: Florida, United States | L27: Virginia | M27: United States | N27: Virginia, United States | O27: decreased quality of life due to mobility and other health issues | P27: 25 | Q27: 21–30% | R27: increased burden on healthcare systems caring for elderly | S27: increased incentives for primary care physicians for the elderly | U27: increase salary for elderly caretakers and primary care of elderly | V27: mobility, independence, health | W27: work out regularly | X27: wellness and health maintenance by taking care of your body | Y27: 3 | Z27: 1 | AA27: 2 | AB27: 2 | AC27: 1 | AD27: 3 | AE27: because for society at a large, immediate interventions that provide the broadest impact are necessary while for individual level, I believe AI innovation is necessary for select individuals to progress and advance the current state of medicine/science | AG27: potential for AI to be used for ill intent | AJ27: Yes | AL27: Yes | AO27: Yes
A28: G1-027 | B28: 1 | C28: 59 | F28: 26 | G28: =IF(F28="","",IF(F28>=Notes!$B$5,"Elderly ("&Notes!$B$5&"+)",IF(F28<=Notes!$B$4,"Student age (≤"&Notes!$B$4&")","Middle-aged ("&(Notes!$B$4+1)&"–"&(Notes!$B$5-1)&")"))) -> Student age (≤29) | H28: Female | J28: Taiwan | K28: Taiwan | L28: Texas | M28: United States | N28: Texas, United States | O28: it’s the cellular, physiological, psychological, and social changes that accrue over time on an individual being | P28: 22 | Q28: 21–30% | R28: shortage of healthcare resources, including nurses, senior homes, home health aid, community spaces. second is social isolation and loneliness. | S28: Care provision. We don’t have a culture of caring for the previous generation like Asian or other countries do. Healthcare isn’t universal, and some older adults run out of resources before they die because now the lifespan is longer and retirement funds are lower. Also, the younger generation bares no obligation to support them, and there is a lack of geriatric care resources. This should be prioritized because the older adult population is exponentially growing, but the resources are not expanding at the same rate. And if we’re lucky, we will all get old so we should all care. | U28: More community and institution level programs for older adult health and longevity (fitness, tech classes, health literacy classes). Some states having policy level plans on aging, like California’s Master Plan on Aging. And some cities like Los Angeles having Departments on Aging that have social work and other services just for older adults. | V28: My memory, having loved ones around me, financial stability | W28: Eat and workout well, don’t drop out of school, and put effort into people. | X28: Wellbeing | Y28: 1 | Z28: 2 | AA28: 3 | AB28: 2 | AC28: 1 | AD28: 3 | AE28: My longevity is the most important to me as an individual because I want to live a long healthy life, and the accessibility of resources contributes to that more greatly than AI does. The accessibility of resources is the most important to society because it can improve the quality of life for older adults on a direct population level. | AG28: It frightens me the amount of states in the US who are not making progress to increase accessibility of older adult resources. It frightens me how little people care. But what excites me is the innovative and interdisciplinary things being implemented in the states that are doing it. Like many OT/PT/RD programs implementing a geriatrics rotation and block in their curriculum. And more nonprofits building social spaces for older adults. | AJ28: Yes | AL28: Yes | AO28: Yes
A29: G1-028 | B29: 1 | C29: 60 | F29: 22 | G29: =IF(F29="","",IF(F29>=Notes!$B$5,"Elderly ("&Notes!$B$5&"+)",IF(F29<=Notes!$B$4,"Student age (≤"&Notes!$B$4&")","Middle-aged ("&(Notes!$B$4+1)&"–"&(Notes!$B$5-1)&")"))) -> Student age (≤29) | H29: Male | I29: Utah | J29: United States | K29: Utah, United States | L29: Maryland | M29: United States | N29: Maryland, United States | O29: Continual process of staying alive | P29: 30 | Q29: 21–30% | R29: Our aging population is increasing due to increased life expectancy, but not enough caregivers. | S29: Promoting elderly care as a profession or family members to take care of aging members. | U29: No | V29: Health, memory, connections | W29: Yes, exercise and social maintenance | X29: maintenance | Y29: 1 | Z29: 3 | AA29: 2 | AB29: 3 | AC29: 1 | AD29: 2 | AE29: Making policies take longer than personal choices, so I ranked on actionable items that I can do to help myself where as I did the reverse order for society to do in order to "keep up" | AG29: I am excited about the advances of medicine that can help me. One thing that scares me is the rapid technological innovation and wondering if AI would have any detrimenting consequences | AJ29: Yes | AL29: Yes | AO29: Yes
A30: G1-029 | B30: 1 | C30: 61 | F30: 22 | G30: =IF(F30="","",IF(F30>=Notes!$B$5,"Elderly ("&Notes!$B$5&"+)",IF(F30<=Notes!$B$4,"Student age (≤"&Notes!$B$4&")","Middle-aged ("&(Notes!$B$4+1)&"–"&(Notes!$B$5-1)&")"))) -> Student age (≤29) | H30: Female | J30: United States | K30: United States | L30: Maryland | M30: United States | N30: Maryland, United States | O30: Wear and tear of the body over time | P30: 30 | Q30: 21–30% | R30: Not enough caretakers | S30: Financial support like Medicare and SSDI, people need to be supported especially at their weakest. So many in poverty at an older age | U30: Yes, some federal programs but not nearly enough | V30: Bone/muscule strength, posture and flexibility, mental stability | W30: Yes, weightlifting | X30: The ability to maintain whats in your control, genetics aside | Y30: 2 | Z30: 3 | AA30: 1 | AB30: 2 | AC30: 3 | AD30: 1 | AE30: Innovations don’t matter if they’re not accessible to those who need it | AG30: Excited about AI creating new innovations, worried that their effects will be limited to those who can afford breakthrough treatments | AJ30: Yes | AL30: Yes | AO30: Yes
A31: G1-030 | B31: 1 | C31: 62 | F31: 23 | G31: =IF(F31="","",IF(F31>=Notes!$B$5,"Elderly ("&Notes!$B$5&"+)",IF(F31<=Notes!$B$4,"Student age (≤"&Notes!$B$4&")","Middle-aged ("&(Notes!$B$4+1)&"–"&(Notes!$B$5-1)&")"))) -> Student age (≤29) | H31: Female | I31: Maryland | J31: United States | K31: Maryland, United States | L31: Maryland | M31: United States | N31: Maryland, United States | O31: The process of growing older over time and changing physically as time moves forward. | P31: 25 | Q31: 21–30% | R31: Healthcare access and cognitive decline | S31: Healthcare access and affordability. The aging population requires more medical care and daily support, which is expensive. It should be prioritized to make healthcare more accessible and affordable because everyone deserves to maintain a good quality of life as they age without the financial burden on themselves or their families. | U31: I am not certain. | V31: Good health, sharp mind, independence | W31: Prioritize my health by staying active and eating healthy. | X31: Being physically and mentally well to enjoy life, make my own decisions, and take care of myself as I age. | Y31: 1 | Z31: 2 | AA31: 3 | AB31: 1 | AC31: 3 | AD31: 2 | AE31: I ranked them for myself this way because it is important for me to maintain longevity and make healthcare more accessible. For society, I think healthcare access is lower on the priority list, while predicting disease is more important. All of these statements are important and should be prioritized to help the aging population. | AG31: It would be amazing to use AI to predict diseases, which excites me. It frightens me that this could create a larger gap in healthcare accessibility because these tools could become extremely expensive. | AJ31: Yes | AL31: Yes | AO31: Yes
A32: G1-031 | B32: 1 | C32: 63 | F32: 25 | G32: =IF(F32="","",IF(F32>=Notes!$B$5,"Elderly ("&Notes!$B$5&"+)",IF(F32<=Notes!$B$4,"Student age (≤"&Notes!$B$4&")","Middle-aged ("&(Notes!$B$4+1)&"–"&(Notes!$B$5-1)&")"))) -> Student age (≤29) | H32: Male | I32: Pennsylvania | J32: United States | K32: Pennsylvania, United States | L32: Maryland | M32: United States | N32: Maryland, United States | O32: The process of getting older and quality of life decreasing as a result. | P32: 35 | Q32: Over 30% | R32: The number of people above the age of 65 is increasing, so access to proper healthcare is a major challenge. | S32: Ensuring that there are proper resources in place to care for the aging population. This should be prioritized because without proper care, QOL will decrease. | U32: Money, resources, geographic limitations. | V32: My physical health, my mental health, and connections to family/friends. | W32: Stay in physical and mental shape, communicate with others, continue to learn and grow. | X32: Foundational principles of a healthy life. | Y32: 2 | Z32: 2 | AA32: 2 | AB32: 1 | AC32: 3 | AD32: 2 | AE32: Longevity is important, but I do not think that is necessarily a goal of everyone unless it is in parallel with QOL increased. Democratizing science should always be a goal so that access to health solutions is not narrowed to the upper class. Applying AI will help and is already happening. | AG32: Excites: Access to new healthcare modalities; Frightens: Access to new healthcare modalities only for those who can afford it | AJ32: Yes | AL32: Yes | AO32: Yes | AR32: personal ranks repeat a number (as answered)
A33: G1-032 | B33: 1 | C33: 65 | F33: 20 | G33: =IF(F33="","",IF(F33>=Notes!$B$5,"Elderly ("&Notes!$B$5&"+)",IF(F33<=Notes!$B$4,"Student age (≤"&Notes!$B$4&")","Middle-aged ("&(Notes!$B$4+1)&"–"&(Notes!$B$5-1)&")"))) -> Student age (≤29) | H33: Male | I33: Massachusetts | J33: United States | K33: Massachusetts, United States | L33: Maryland | M33: United States | N33: Maryland, United States | O33: When the lifespan of your body’s tissues and organs starts coming to an end. | P33: 15 | Q33: 15% or less | R33: cancer | S33: fitness and overall health | U33: more fitness regimes, less processed foods | V33: basketball, health, memory | W33: consistent habits | X33: Everything | Y33: 1 | Z33: 2 | AA33: 3 | AB33: 3 | AC33: 1 | AD33: 2 | AE33: i think the three are all related in some way so the order is varying | AG33: AI excites, AI frightens | AJ33: Yes | AL33: Yes | AO33: Yes
A34: G1-033 | B34: 1 | C34: 66 | F34: 21 | G34: =IF(F34="","",IF(F34>=Notes!$B$5,"Elderly ("&Notes!$B$5&"+)",IF(F34<=Notes!$B$4,"Student age (≤"&Notes!$B$4&")","Middle-aged ("&(Notes!$B$4+1)&"–"&(Notes!$B$5-1)&")"))) -> Student age (≤29) | H34: Male | I34: Maryland | J34: United States | K34: Maryland, United States | L34: Maryland | M34: United States | N34: Maryland, United States | O34: Growing older + the accompanying bio. / phys. changes | P34: 20 | Q34: 16–20% | R34: Aging safely both biologically + socially | S34: Dangerous home design for old people | U34: Not huge movements | V34: Physical activity, good diet, good social connections | W34: Yes | X34: Keeping up to date with housing keeping/health stuff | Y34: 1 | Z34: 2 | AA34: 2 | AB34: 2 | AC34: 2 | AD34: 2 | AE34: I care more about repod. health, but i think society overall cares (not too much) about all 3 the same | AG34: Privacy for AI | AJ34: Yes | AL34: Yes | AO34: Yes | AR34: personal ranks repeat a number (as answered); societal ranks repeat a number (as answered)
A35: G1-034 | B35: 1 | C35: 67 | F35: 21 | G35: =IF(F35="","",IF(F35>=Notes!$B$5,"Elderly ("&Notes!$B$5&"+)",IF(F35<=Notes!$B$4,"Student age (≤"&Notes!$B$4&")","Middle-aged ("&(Notes!$B$4+1)&"–"&(Notes!$B$5-1)&")"))) -> Student age (≤29) | H35: Male | I35: Connecticut | J35: United States | K35: Connecticut, United States | L35: Maryland | M35: United States | N35: Maryland, United States | O35: Getting older / biological age increasing | P35: 23 | Q35: 21–30% | R35: alzheimer's / cognitive diseases | S35: Prioritizing disability awareness and having more accessiblity in public buildings | U35: Rarely | V35: good relationships, good health, purpose | W35: Yes, there are lots of intentional actions I can take for each thing. | X35: The important things for me in life is maintaining close relationships with friends and family, keeping my body health, and having a career/hobbies that fulfills me. | Y35: 2 | Z35: 3 | AA35: 1 | AB35: 2 | AC35: 3 | AD35: 1 | AE35: I think AI can be a double edged sword that leads to more harm than good. | AG35: It's exciting we will get advances in health care that further longevity but the thought of AI corrupting current systems is scary. | AJ35: Yes | AL35: No | AO35: Yes
A36: G1-035 | B36: 1 | C36: 68 | F36: 25 | G36: =IF(F36="","",IF(F36>=Notes!$B$5,"Elderly ("&Notes!$B$5&"+)",IF(F36<=Notes!$B$4,"Student age (≤"&Notes!$B$4&")","Middle-aged ("&(Notes!$B$4+1)&"–"&(Notes!$B$5-1)&")"))) -> Student age (≤29) | H36: Female | I36: Maryland | J36: United States | K36: Maryland, United States | L36: Maryland | M36: United States | N36: Maryland, United States | O36: Natural process that happens through time as you reach the end of your physical life. I think lifestyle things can effect the aging process, like stress, diet, mental/emotional/physical health, and the environment you're in | P36: 20 | Q36: 16–20% | R36: Ability to maintain a good standard of living as they get older (lifestyle and community) | S36: I think overall as people age they become less active and it becomes increasingly difficult for them to get to place like doctors appts, physical therapy, the gym to workout, and staying connected with people as life becomes more isolated. I think short term, getting the aging population to be more active before they become too old can be a immediate short term solution, and more of a preventative measure for the future | U36: I think it has to start before it's too late - it is challenging for middle ages adults to stay healthy and active due to the "hustle culture" and long work hours and commuting, so unhealthy habits (intentially or unintentially) begin before it matters. But emphasizing the importance of health and then also creating systems to help older people have access to appointments and help recover after injuries and help build a community for them | V36: Physical health (ability to walk/lift things), mental health, and spiritual health | W36: Consistency from being young through life until I'm older | X36: Through prioritizing physical, mental, and spiritual health, one can maintain a healthy outlook on life to allow themselves to age smoothly and to be there for the next generations after them. | Y36: 2 | Z36: 1 | AA36: 3 | AB36: 2 | AC36: 3 | AD36: 1 | AE36: For me, I think having things accessible, affordable, and generalizable to all is really important and the only way to help the population as a whole with aging and health. To me if feels like a more root cause approach and helps fix the systems that are on going. For society, I see them as prioritizing the application of machine learning to solve problems with the world with AI and data centers expanding, and there are benefits within that, but I don't think it should be the first importance and takes the human-ness out of aging, disease, adn the individual experience. | AG36: I think it's exciting that there are a lot of advancements contributing to the well-being of individuals and help with longevity and improvement for the heath of individuals and that there is important research to help those that need it. What frightens me is stretching to far away form human nature and relying too much on technology and AI | AJ36: Yes | AL36: Yes | AO36: Yes
A37: G1-036 | B37: 1 | C37: 69 | F37: 22 | G37: =IF(F37="","",IF(F37>=Notes!$B$5,"Elderly ("&Notes!$B$5&"+)",IF(F37<=Notes!$B$4,"Student age (≤"&Notes!$B$4&")","Middle-aged ("&(Notes!$B$4+1)&"–"&(Notes!$B$5-1)&")"))) -> Student age (≤29) | H37: Male | I37: Texas | J37: United States | K37: Texas, United States | L37: Rhode Island | M37: United States | N37: Rhode Island, United States | O37: The components of the body, either individually or collectively, working less well resulting in progressive degeneration of the organism. | P37: 25 | Q37: 21–30% | R37: Lack of primary care doctors and a need for increase in federal funding for specialty residency spots. Lack of knowledge/keeping up with the rapid progression in technology/AI. Self-centered, isolationist culture in America leading to separation of elders from their families and communities. | S37: Increasing primary care providers. | U37: Incentivizing med students to choose primary care specialties by subsidizing med school tuition if they commit to it. | V37: Good sleeping habits, exercising regularly, eating nutritious foods. | W37: Stay disciplined - never stop doing it so it doesn't start seeming like a challenge. | X37: Helping preserve my health proactively. | Y37: 1 | Z37: 2 | AA37: 3 | AB37: 1 | AC37: 2 | AD37: 3 | AE37: 1 encompasses the second and third options, democratizing and AI will go hand in hand. | AG37: N/A | AJ37: Yes | AL37: Yes | AO37: Yes
A38: G1-037 | B38: 1 | C38: 70 | F38: 23 | G38: =IF(F38="","",IF(F38>=Notes!$B$5,"Elderly ("&Notes!$B$5&"+)",IF(F38<=Notes!$B$4,"Student age (≤"&Notes!$B$4&")","Middle-aged ("&(Notes!$B$4+1)&"–"&(Notes!$B$5-1)&")"))) -> Student age (≤29) | H38: Female | I38: Shanghai | J38: China | K38: Shanghai, China | L38: Maryland | M38: United States | N38: Maryland, United States | O38: the number of years since you born | P38: 30 | Q38: 21–30% | R38: loss of physical function and independence, which can lead to a greater need for medical care and financial support | S38: Financial support should be prioritized by creating more programs to help older adults with their financial needs | U38: yes | V38: A clear mind, a healthy body, financial stability | W38: exercise everyday, work hard | X38: I'm not quite sure what this question is asking | Y38: 3 | Z38: 2 | AA38: 1 | AB38: 3 | AC38: 3 | AD38: 3 | AE38: For me, boosting longevity is the most important goal, while the other twos are more important from a societal perspective because they provide practical solutions. | AG38: Boosting longevity is the most exciting to me, but applying machine learning models to this area is a little frightens. | AJ38: Yes | AL38: Yes | AO38: Yes | AR38: societal ranks repeat a number (as answered)
A39: G1-038 | B39: 1 | C39: 71 | F39: 22 | G39: =IF(F39="","",IF(F39>=Notes!$B$5,"Elderly ("&Notes!$B$5&"+)",IF(F39<=Notes!$B$4,"Student age (≤"&Notes!$B$4&")","Middle-aged ("&(Notes!$B$4+1)&"–"&(Notes!$B$5-1)&")"))) -> Student age (≤29) | H39: Female | I39: Beijing | J39: China | K39: Beijing, China | L39: Ontario | M39: Canada | N39: Ontario, Canada | O39: The long term decrease in health, growing older in age, as well as the | P39: 20 | Q39: 16–20% | R39: Social barrier such as Ageism, discrimination and preconceived notion of those who are older. | S39: Raising awareness regarding aging, it should be prioritized as it is a simple first step to eliminate Ageism. | U39: Incorporating these knowledge through educational institutions. | V39: Health, wealth, social connections | W39: Regular exercise, investments, regular contact | X39: The above are things that shows cumulative effect, they will not be wasted. | Y39: 3 | Z39: 1 | AA39: 2 | AB39: 3 | AC39: 1 | AD39: 2 | AE39: Ranked democratizing the knowledge as most important because it kind of relates to what I mentioned above. Health solutions are vital for maintaining longevity. AI is emerging and it would be great to utilize it to benefit the aging population. Reproductive health not so important, there are other technologies like IVF advancing now. | AG39: Frightens about population longevity stretched to too long and resource on earth becomes more scarce. Also looking forward to see how normal population are able to use AI to better their health. | AJ39: Yes | AL39: Yes | AO39: Yes
A40: G1-039 | B40: 1 | C40: 72 | F40: 23 | G40: =IF(F40="","",IF(F40>=Notes!$B$5,"Elderly ("&Notes!$B$5&"+)",IF(F40<=Notes!$B$4,"Student age (≤"&Notes!$B$4&")","Middle-aged ("&(Notes!$B$4+1)&"–"&(Notes!$B$5-1)&")"))) -> Student age (≤29) | H40: Female | J40: China | K40: China | M40: United States | N40: United States | O40: The natural process of body function getting old | P40: 15 | Q40: 15% or less | R40: Lack of services taking care of old people | S40: Maybe the caring system, as the aging population is in a high demand of being cared for. | U40: There might be some new programs for aging group to get care. | V40: 1. Independent living 2. Talking 3. Thinking | W40: More exercise, enough sleep, and more beneficial programs. | X40: Stay healthy and expecting more aging care programs. | Y40: 3 | Z40: 3 | AA40: 3 | AB40: 3 | AC40: 2 | AD40: 1 | AE40: I used to study bioengineering, so I think as AI actively develops, we may use it as an active tool for human health, it is effective and accurate in data, so could be good for producing health models etc. Then democratize it to the public like a chain. I don’t know much about the first choice. | AG40: Excite: apply AI as a prediction tool in human health Frighten: the ethic problem related to AI use | AJ40: Yes | AL40: Yes | AO40: Yes | AR40: personal ranks repeat a number (as answered)
...

Sheet Tagged Responses
